Workbook

Sheet 預購單 
A1: 建國高中 熱食部午餐便當預購單 | M1: 建國高中 午餐便當預購單 -2
A2: 預購便當請確實填寫班級、數量、金額，收齊費用交至熱食部統計辦理。最後收單期限為11/14(五)中午12:30，請務必將費用收齊辦理，逾時恕不受理。 | M2: 預購便當請確實填寫班級、數量、金額，收齊費用交至熱食部統計辦理。
A3: 請於12:00取餐 | F3: ｜ | G3: 本餐廳所使用使用豬肉原料原產地皆為臺灣。本餐廳未使用輻射汙染食品。 | M3: 請於12:00取餐 | R3: ｜ | S3: 本餐廳所使用使用豬肉原料原產地皆為臺灣。本餐廳未使用輻射汙染食品。
A4: 訂餐聯(熱食部留存) | F4: ｜ | G4: 存根聯(學生留存) | M4: 訂餐聯(熱食部留存) | R4: ｜ | S4: 存根聯(學生留存)
A5: 班級： | F5: ｜ | G5: 班級： | M5: 班級： | R5: ｜ | S5: 班級：
A6: 45978 | D6: =A6 -> 45978 | F6: ｜ | G6: =A6 -> 45978 | J6: =D6 -> 45978 | M6: =A22+1 -> 45981 | P6: =M6 -> 45981 | R6: ｜ | S6: =M6 -> 45981 | V6: =P6 -> 45981
A7: 品 名 | C7: 單價 | D7: 數量 | E7: 小計 | F7: ｜ | G7: 品 名 | I7: 單價 | J7: 訂購座號 | K7: 小計 | M7: 品 名 | O7: 單價 | P7: 數量 | Q7: 小計 | R7: ｜ | S7: 品 名 | U7: 單價 | V7: 數量 | W7: 小計
A8: 1 | B8: 雞腿飯 | C8: =[1]週菜單!C7 -> 110 | F8: ｜ | G8: 1 | H8: 雞腿飯 | I8: =C8 -> 110 | M8: 1 | N8: 雞腿飯 | O8: =[1]週菜單!O7 -> 110 | R8: ｜ | S8: 1 | T8: 雞腿飯 | U8: =O8 -> 110
A9: 2 | B9: 卡啦雞排飯 | C9: =[1]週菜單!C8 -> 85 | F9: ｜ | G9: 2 | H9: 卡啦雞排飯 | I9: =C9 -> 85 | M9: 2 | N9: 七味雞排 | O9: =[1]週菜單!O8 -> 85 | R9: ｜ | S9: 2 | T9: 七味雞排 | U9: =O9 -> 85
A10: 3 | B10: 沙茶豬柳 | C10: =[1]週菜單!C9 -> 85 | F10: ｜ | G10: 3 | H10: 沙茶豬柳 | I10: =C10 -> 85 | M10: 3 | N10: 鐵板豬柳 | O10: =[1]週菜單!O9 -> 85 | R10: ｜ | S10: 3 | T10: 鐵板豬柳 | U10: =O10 -> 85
A11: 4 | B11: 香腸蛋炒飯 | C11: =[1]週菜單!C11 -> 80 | F11: ｜ | G11: 4 | H11: 香腸蛋炒飯 | I11: =C11 -> 80 | M11: 4 | N11: 蝦捲香腸蓋飯 | O11: =[1]週菜單!O11 -> 80 | R11: ｜ | S11: 4 | T11: 蝦捲香腸蓋飯 | U11: =O11 -> 80
A12: 5 | B12: 玉米濃湯餃 | C12: =[1]週菜單!C22 -> 80 | F12: ｜ | G12: 5 | H12: 玉米濃湯餃 | I12: =C12 -> 80 | M12: 5 | N12: 餛飩貢丸乾拌麵 | O12: =[1]週菜單!O22 -> 80 | R12: ｜ | S12: 5 | T12: 餛飩貢丸乾拌麵 | U12: =O12 -> 80
A13: 6 | B13: 素食便當 | C13: 85 | F13: ｜ | G13: 6 | H13: 素食便當 | I13: 85
A14: =A6+1 -> 45979 | D14: =A14 -> 45979 | F14: ｜ | G14: =A14 -> 45979 | J14: =D14 -> 45979 | M14: =M6+1 -> 45982 | P14: =M14 -> 45982 | R14: ｜ | S14: =M14 -> 45982 | V14: =P14 -> 45982
A15: 品 名 | C15: 單價 | D15: 數量 | E15: 小計 | F15: ｜ | G15: 品 名 | I15: 單價 | J15: 訂購座號 | K15: 小計 | M15: 品 名 | O15: 單價 | P15: 數量 | Q15: 小計 | R15: ｜ | S15: 品 名 | U15: 單價 | V15: 數量 | W15: 小計
A16: 1 | B16: 雞腿飯 | C16: =[1]週菜單!I7 -> 110 | F16: ｜ | G16: 1 | H16: 雞腿飯 | I16: 110 | M16: 1 | N16: 雞腿飯 | O16: =[1]週菜單!U7 -> 110 | R16: ｜ | S16: 1 | T16: 雞腿飯 | U16: 110
A17: 2 | B17: 三杯雞丁 | C17: =[1]週菜單!I8 -> 85 | F17: ｜ | G17: 2 | H17: 三杯雞丁 | I17: 85 | M17: 2 | N17: 酥炸腿排 | O17: =[1]週菜單!U8 -> 85 | R17: ｜ | S17: 2 | T17: 酥炸腿排 | U17: 85
A18: 3 | B18: BBQ烤肉 | C18: =[1]週菜單!I9 -> 85 | F18: ｜ | G18: 3 | H18: BBQ烤肉 | I18: 85 | M18: 3 | N18: 味噌薑燒豬 | O18: =[1]週菜單!U9 -> 85 | R18: ｜ | S18: 3 | T18: 味噌薑燒豬 | U18: 85
A19: 4 | B19: 紅燒牛肉燴飯 | C19: 120 | F19: ｜ | G19: 4 | H19: 紅燒牛肉燴飯 | I19: 120 | M19: 4 | N19: 鮭魚蛋炒飯 | O19: =[1]週菜單!U11 -> 80 | R19: ｜ | S19: 4 | T19: 鮭魚蛋炒飯 | U19: 80
A20: 5 | B20: 滷蛋肉燥拌麵 | C20: =[1]週菜單!I24 -> 80 | F20: ｜ | G20: 5 | H20: 滷蛋肉燥拌麵 | I20: 80 | M20: 5 | N20: 紅燒排骨麵 | O20: =[1]週菜單!U24 -> 80 | R20: ｜ | S20: 5 | T20: 紅燒排骨麵 | U20: 80
A21: 6 | B21: 素食便當 | C21: 85 | F21: ｜ | G21: 6 | H21: 素食便當 | I21: 85
A22: =A14+1 -> 45980 | D22: =A22 -> 45980 | F22: ｜ | G22: =A22 -> 45980 | J22: =D22 -> 45980 | P22: =M22 -> 0 | R22: ｜ | V22: =P22 -> 0
A23: 品 名 | C23: 單價 | D23: 數量 | E23: 小計 | F23: ｜ | G23: 品 名 | I23: 單價 | J23: 訂購座號 | K23: 小計 | M23: 品 名 | O23: 單價 | P23: 數量 | Q23: 小計 | R23: ｜ | S23: 品 名 | U23: 單價 | V23: 數量 | W23: 小計
A24: 1 | B24: 雞腿飯 | C24: =[1]週菜單!O7 -> 110 | F24: ｜ | G24: 1 | H24: 雞腿飯 | I24: 110 | M24: 1 | O24: =[1]週菜單!AA7 -> 110 | R24: ｜ | S24: 1 | U24: 110
A25: 2 | B25: 椒鹽雞丁 | C25: =[1]週菜單!O8 -> 85 | F25: ｜ | G25: 2 | H25: 椒鹽雞丁 | I25: 85 | M25: 2 | O25: =[1]週菜單!AA8 -> 85 | R25: ｜ | S25: 2 | U25: 85
A26: 3 | B26: 招牌燒肉 | C26: =[1]週菜單!O9 -> 85 | F26: ｜ | G26: 3 | H26: 招牌燒肉 | I26: 85 | M26: 3 | O26: =[1]週菜單!AA9 -> 85 | R26: ｜ | S26: 3 | U26: 85
A27: 4 | B27: 火腿蛋炒飯 | C27: 80 | F27: ｜ | G27: 4 | H27: 火腿蛋炒飯 | I27: 80 | M27: 4 | O27: 80 | R27: ｜ | S27: 4 | U27: 80
A28: 5 | B28: 白醬培根義大利麵 | C28: 80 | F28: ｜ | G28: 5 | H28: 白醬培根義大利麵 | I28: 80 | M28: 5 | O28: 80 | R28: ｜ | S28: 5 | U28: 80
A29: 6 | B29: 素食便當 | C29: 85 | F29: ｜ | G29: 6 | H29: 素食便當 | I29: 85
A30: =A22+1 -> 45981 | D30: =A30 -> 45981 | F30: ｜ | G30: =A30 -> 45981 | J30: =D30 -> 45981 | M30: =M22+1 -> 1 | P30: =M30 -> 1 | R30: ｜ | S30: =M30 -> 1 | V30: =P30 -> 1
A31: 品 名 | C31: 單價 | D31: 數量 | E31: 小計 | F31: ｜ | G31: 品 名 | I31: 單價 | J31: 訂購座號 | K31: 小計 | M31: 品 名 | O31: 單價 | P31: 數量 | Q31: 小計 | R31: ｜ | S31: 品 名 | U31: 單價 | V31: 數量 | W31: 小計
A32: 1 | B32: 雞腿飯 | C32: 110 | F32: ｜ | G32: 1 | H32: 雞腿飯 | I32: 110 | M32: 1 | N32: 雞腿飯 | O32: =[1]週菜單!U21 -> 0 | R32: ｜ | S32: 1 | T32: 雞腿飯 | U32: 110
A33: 2 | B33: 鐵路便當 | C33: 85 | F33: ｜ | G33: 2 | H33: 鐵路便當 | I33: 85 | M33: 2 | N33: 酥炸腿排 | O33: =[1]週菜單!U22 -> 80 | R33: ｜ | S33: 2 | T33: 酥炸腿排 | U33: 85
A34: 3 | B34: 燒烤腿排 | C34: 85 | F34: ｜ | G34: 3 | H34: 燒烤腿排 | I34: 85 | M34: 3 | N34: 味噌薑燒豬 | O34: =[1]週菜單!U23 -> 80 | R34: ｜ | S34: 3 | T34: 味噌薑燒豬 | U34: 85
A35: 4 | B35: 南蠻雞肉丼 | C35: 80 | F35: ｜ | G35: 4 | H35: 南蠻雞肉丼 | I35: 80 | M35: 4 | N35: 鮭魚蛋炒飯 | O35: =[1]週菜單!U25 -> 0 | R35: ｜ | S35: 4 | T35: 鮭魚蛋炒飯 | U35: 80
A36: 5 | B36: 元氣小火鍋 | C36: 80 | F36: ｜ | G36: 5 | H36: 元氣小火鍋 | I36: 80 | M36: 5 | N36: 紅燒排骨麵 | O36: =[1]週菜單!U38 -> 0 | R36: ｜ | S36: 5 | T36: 紅燒排骨麵 | U36: 80
A37: 6 | B37: 素食便當 | C37: 85 | F37: ｜ | G37: 6 | H37: 素食便當 | I37: 85
A38: =A30+1 -> 45982 | D38: =A38 -> 45982 | F38: ｜ | G38: =A38 -> 45982 | J38: =D38 -> 45982 | P38: =M38 -> 0 | R38: ｜ | V38: =P38 -> 0
A39: 品 名 | C39: 單價 | D39: 數量 | E39: 小計 | F39: ｜ | G39: 品 名 | I39: 單價 | J39: 訂購座號 | K39: 小計 | M39: 品 名 | O39: 單價 | P39: 數量 | Q39: 小計 | R39: ｜ | S39: 品 名 | U39: 單價 | V39: 數量 | W39: 小計
A40: 1 | B40: 雞腿飯 | C40: 110 | F40: ｜ | G40: 1 | H40: 雞腿飯 | I40: 110 | M40: 1 | O40: =[1]週菜單!AA21 -> 0 | R40: ｜ | S40: 1 | U40: 110
...

Sheet 週菜單
A1: 建中熱食部 午餐菜單
H2: 依教育部學校午餐食物內容及營養基準，每日午餐供應全榖雜糧類5~6.5份、豆魚蛋肉類2~2.5份、蔬菜類1.5~2份、油脂與堅果種子類2.5~3份。
A4: 45978 | G4: =A4+1 -> 45979 | M4: =G4+1 -> 45980 | S4: =M4+1 -> 45981 | Y4: =S4+1 -> 45982 | AE4: =Y4+1 -> 45983
A5: =A4 -> 45978 | G5: =G4 -> 45979 | M5: =M4 -> 45980 | S5: =S4 -> 45981 | Y5: =Y4 -> 45982 | AE5: =AE4 -> 45983
A6: 項次 | B6: 餐別 | C6: 價格 | D6: 主要烹調方式 | E6: kcal | F6: 過敏原 | G6: 項次 | H6: 餐別 | I6: 價格 | J6: 主要烹調方式 | K6: kcal | L6: 過敏原 | M6: 項次 | N6: 餐別 | O6: 價格 | P6: 主要烹調方式 | Q6: kcal | R6: 過敏原 | S6: 項次 | T6: 餐別 | U6: 價格 | V6: 主要烹調方式 | W6: kcal | X6: 過敏原 | Y6: 項次 | Z6: 餐別 | AA6: 價格 | AB6: 主要烹調方式 | AC6: kcal | AD6: 過敏原
A7: 1 | B7: 雞腿飯 | C7: 110 | E7: ='1117'!J4 -> 838.5 | G7: 1 | H7: 雞腿飯 | I7: 110 | K7: ='1117'!J12 -> 754.4 | M7: 1 | N7: 雞腿飯 | O7: 110 | Q7: ='1117'!J20 -> 782.6 | S7: 1 | T7: 雞腿飯 | U7: 110 | W7: ='1117'!J28 -> 772.9 | Y7: 1 | Z7: 雞腿飯 | AA7: 110 | AC7: 762.7 | AE7: 簡餐 | AF7: 泰式打拋豬 | AG7: 75
A8: 2 | B8: 卡啦雞排飯 | C8: 85 | D8: 炸 | E8: ='1117'!J5 -> 718.3 | F8: =VLOOKUP(B8,簡餐資料庫!$A:$E,5,FALSE) -> H | G8: 2 | H8: 三杯雞丁 | I8: 85 | J8: 炒 | K8: ='1117'!J13 -> 640.8 | L8: =VLOOKUP(H8,簡餐資料庫!$A:$E,5,FALSE) -> 0 | M8: 2 | N8: 椒鹽雞丁 | O8: 85 | P8: 滷 | Q8: ='1117'!J21 -> 666.6 | R8: =VLOOKUP(N8,簡餐資料庫!$A:$E,5,FALSE) -> H | S8: 2 | T8: 鐵路便當 | U8: 85 | V8: 滷 | W8: ='1117'!J29 -> 704.4 | X8: =VLOOKUP(T8,簡餐資料庫!$A:$E,5,FALSE) -> EFJ | Y8: 2 | Z8: 香酥雞排 | AA8: 85 | AB8: 炸 | AC8: 721.7 | AD8: H | AE8: 簡餐 | AF8: 蒜香豬肉 | AG8: 75
A9: 3 | B9: 沙茶豬柳 | C9: 85 | D9: 炒 | E9: ='1117'!J6 -> 718 | F9: =VLOOKUP(B9,簡餐資料庫!$A:$E,5,FALSE) -> D | G9: 3 | H9: BBQ烤肉 | I9: 85 | J9: 烤 | K9: ='1117'!J14 -> 629.4 | L9: =VLOOKUP(H9,簡餐資料庫!$A:$E,5,FALSE) -> 0 | M9: 3 | N9: 招牌燒肉 | O9: 85 | P9: 烤 | Q9: ='1117'!J22 -> 664.5 | R9: =VLOOKUP(N9,簡餐資料庫!$A:$E,5,FALSE) -> 0 | S9: 3 | T9: 燒烤腿排 | U9: 85 | V9: 烤 | W9: ='1117'!J30 -> 657.2 | X9: =VLOOKUP(T9,簡餐資料庫!$A:$E,5,FALSE) -> 0 | Y9: 3 | Z9: 紅燒雞丁 | AA9: 85 | AB9: 炒 | AC9: 681.1 | AE9: 簡餐 | AF9: 和風親子丼 | AG9: 70
A10: 4 | B10: 滷香排骨 | C10: 85 | D10: 滷 | E10: ='1117'!J7 -> 713.5 | F10: =VLOOKUP(B10,簡餐資料庫!$A:$E,5,FALSE) -> 0 | G10: 4 | H10: 日式魚排 | I10: 85 | J10: 炸 | K10: ='1117'!J15 -> 666.8 | L10: =VLOOKUP(H10,簡餐資料庫!$A:$E,5,FALSE) -> DH | M10: 4 | N10: 糖醋里肌 | O10: 85 | P10: 炒 | Q10: ='1117'!J23 -> 695 | R10: =VLOOKUP(N10,簡餐資料庫!$A:$E,5,FALSE) -> H | S10: 4 | T10: 宮保豬肉 | U10: 85 | V10: 炸 | W10: ='1117'!J31 -> 690.1 | X10: =VLOOKUP(T10,簡餐資料庫!$A:$E,5,FALSE) -> 0 | Y10: 4 | Z10: 黑胡椒豬肉 | AA10: 85 | AB10: 炒 | AC10: 672.1 | AE10: 簡餐 | AF10: 和風親子丼 | AG10: 70
A11: 5 | B11: 香腸蛋炒飯 | C11: 80 | D11: 炒 | E11: ='1117'!J8 -> 629.8 | F11: =VLOOKUP(B11,簡餐資料庫!$A:$E,5,FALSE) -> EJ | G11: 5 | H11: 紅燒牛肉燴飯 | I11: 120 | J11: 燴 | K11: ='1117'!J16 -> 645.6 | L11: =VLOOKUP(H11,簡餐資料庫!$A:$E,5,FALSE) -> E | M11: 5 | N11: 火腿蛋炒飯 | O11: 80 | P11: 烤 | Q11: ='1117'!J24 -> 563.6 | R11: =VLOOKUP(N11,簡餐資料庫!$A:$E,5,FALSE) -> EJ | S11: 5 | T11: 南蠻雞肉丼 | U11: 80 | V11: 燴 | W11: ='1117'!J32 -> 656.5 | X11: =VLOOKUP(T11,簡餐資料庫!$A:$E,5,FALSE) -> H | Y11: 5 | Z11: 奶油培根燴飯 | AA11: 80 | AB11: 燴 | AC11: 563.8 | AD11: CEJ | AE11: 簡餐 | AF11: 素食便當 | AG11: 75
A12: ★ | B12: 週一蔬食便當 | C12: 85 | D12: 含6樣蔬食菜色
B13: 便當副菜 | H13: 便當副菜 | N13: 便當副菜 | T13: 便當副菜 | Z13: 便當副菜 | AE13: 便當副菜
B14: 季節時蔬 | H14: 季節時蔬 | N14: 季節時蔬 | T14: 季節時蔬 | Z14: 季節時蔬 | AF14: 季節時蔬
B15: 泡菜冬粉 | F15: =VLOOKUP(B15,簡餐資料庫!$A:$E,5,FALSE) -> 0 | H15: 雙色南瓜 | L15: =VLOOKUP(H15,簡餐資料庫!$A:$E,5,FALSE) -> 0 | N15: 青椒豆干 | R15: =VLOOKUP(N15,簡餐資料庫!$A:$E,5,FALSE) -> F | T15: 韭菜豆芽 | X15: =VLOOKUP(T15,簡餐資料庫!$A:$E,5,FALSE) -> 0 | Z15: 小黃瓜素雞 | AD15: F | AF15: 咖哩馬鈴薯
B16: 西芹鮮菇 | F16: =VLOOKUP(B16,簡餐資料庫!$A:$E,5,FALSE) -> 0 | H16: 玉筍花椰 | L16: =VLOOKUP(H16,簡餐資料庫!$A:$E,5,FALSE) -> 0 | N16: 三杯麵腸 | R16: =VLOOKUP(N16,簡餐資料庫!$A:$E,5,FALSE) -> H | T16: 玉米豆腐 | X16: =VLOOKUP(T16,簡餐資料庫!$A:$E,5,FALSE) -> F | Z16: 咖哩洋芋 | AF16: 豆芽炒豆腸
B17: 毛豆紅絲炒蛋 | F17: =VLOOKUP(B17,簡餐資料庫!$A:$E,5,FALSE) -> E | H17: 三色干絲 | L17: =VLOOKUP(H17,簡餐資料庫!$A:$E,5,FALSE) -> F | N17: 針菇大黃瓜 | R17: =VLOOKUP(N17,簡餐資料庫!$A:$E,5,FALSE) -> 0 | T17: 塔香海帶根 | X17: =VLOOKUP(T17,簡餐資料庫!$A:$E,5,FALSE) -> 0 | Z17: 香菇四季豆 | AF17: 培根玉米
AF18: 炒高麗菜
B19: 鐵板豆芽
A22: 6 | B22: 滷味燙套餐 | C22: 80 | E22: ='1117'!J9 -> 546 | F22: =VLOOKUP(B22,麵食資料庫!$A:$E,5,FALSE) -> DEFH | G22: 6 | H22: 韓式部隊鍋 | I22: 80 | K22: ='1117'!J17 -> 527.8 | L22: =VLOOKUP(H22,麵食資料庫!$A:$E,5,FALSE) -> CDHJ | M22: 6 | N22: 什錦鍋燒意麵 | O22: 80 | Q22: ='1117'!J25 -> 546 | R22: =VLOOKUP(N22,麵食資料庫!$A:$E,5,FALSE) -> DH | S22: 6 | T22: 紅燒牛肉麵 | U22: 130 | W22: ='1117'!J33 -> 511.9 | X22: =VLOOKUP(T22,麵食資料庫!$A:$E,5,FALSE) -> H | Y22: 6 | Z22: 滷味燙套餐 | AA22: 80 | AC22: 546 | AD22: DEFH | AE22: 麵食 | AF22: 雞排奶油培根麵 | AG22: 75
A23: 7 | B23: 玉米濃湯餃 | C23: 80 | E23: ='1117'!J10 -> 572.7 | F23: =VLOOKUP(B23,麵食資料庫!$A:$E,5,FALSE) -> CEHJ | G23: 7 | H23: 叉燒醬油拉麵 | I23: 80 | K23: ='1117'!J18 -> 509.5 | L23: =VLOOKUP(H23,麵食資料庫!$A:$E,5,FALSE) -> DEH | M23: 7 | N23: 水餃 | O23: 80 | Q23: ='1117'!J26 -> 605.5 | R23: =VLOOKUP(N23,麵食資料庫!$A:$E,5,FALSE) -> H | S23: 7 | T23: 元氣小火鍋 | U23: 80 | W23: ='1117'!J34 -> 435.9 | X23: =VLOOKUP(T23,麵食資料庫!$A:$E,5,FALSE) -> DEH | Y23: 7 | Z23: 麻辣臭豆腐鴨血 | AA23: 80 | AC23: 527.8 | AD23: FH | AE23: 麵食 | AF23: 培根鮪魚義大利麵 | AG23: 75
A24: 8 | B24: 雞排乾拌麵 | C24: 80 | E24: ='1117'!J11 -> 583.7 | F24: =VLOOKUP(B24,麵食資料庫!$A:$E,5,FALSE) -> HJ | G24: 8 | H24: 滷蛋肉燥拌麵 | I24: 80 | K24: ='1117'!J19 -> 575.2 | L24: =VLOOKUP(H24,麵食資料庫!$A:$E,5,FALSE) -> EFH | M24: 8 | N24: 白醬培根義大利麵 | O24: 80 | Q24: ='1117'!J27 -> 652.5 | R24: =VLOOKUP(N24,麵食資料庫!$A:$E,5,FALSE) -> EHJ | S24: 8 | T24: 白油炒手麵 | U24: 80 | W24: ='1117'!J35 -> 506.8 | X24: =VLOOKUP(T24,麵食資料庫!$A:$E,5,FALSE) -> H | Y24: 8 | Z24: 泡菜燒肉拌麵 | AA24: 80 | AC24: 495.7 | AD24: EFH | AE24: 麵食 | AF24: 水餃 | AG24: 70
A26: 本餐廳所使用使用豬肉原料原產地皆為臺灣。未使用輻射汙染食品。
A27: 本菜單部分食材含有衛福部公告11種過敏原，不適合對其過敏體質者食用，有關食材資訊請至校園食材登錄平臺查詢。 過敏原標示：於菜色名稱後方：Ａ甲殼類、Ｂ花生類、Ｃ奶類、D魚類、E蛋類、F豆類、G堅果類、H含麩類、I芒果、J含亞硝酸鹽類、K芝麻類
A28: 熱食部販售之產品食材來源皆有履歷登錄於[教育部校園食材登錄平台]，請各位同學安心食用。連大莊公司關心您

Sheet 1117
A1: 熱食部 週菜單熱量參考表
A2: 【本餐廳豬肉及豬肉加工製品一律使用台灣國產豬肉】
A3: 日期 | B3: 星期 | C3: 菜單 | D3: 全榖雜糧* | E3: 油脂與堅果種子* | F3: 蔬菜* | G3: 乳品* | H3: 水果* | I3: 豆魚蛋肉* | J3: 熱量* | K3: 蛋白質 | L3: 脂肪 | M3: 醣類 | N3: 副菜
A4: 45978 | B4: =A4 -> 45978 | C4: =週菜單!B7 -> 雞腿飯 | D4: 6.5 | E4: 2.6 | F4: 1 | I4: 3.5 | J4: =K4*4+L4*9+M4*4 -> 838.5 | K4: =D4*2+F4*1+G4*8+I4*7 -> 38.5 | L4: =E4*5+G4*8+I4*5 -> 30.5 | M4: =D4*15+F4*5+H4*15+G4*12 -> 102.5 | N4: =週菜單!B14 -> 季節時蔬
C5: =週菜單!B8 -> 卡啦雞排飯 | D5: 6 | E5: 2.2 | F5: 1.2 | I5: 2.5 | J5: =K5*4+L5*9+M5*4 -> 718.3 | K5: =D5*2+F5*1+G5*8+I5*7 -> 30.7 | L5: =E5*5+G5*8+I5*5 -> 23.5 | M5: =D5*15+F5*5+H5*15+G5*12 -> 96 | N5: =週菜單!B15 -> 泡菜冬粉
C6: =週菜單!B9 -> 沙茶豬柳 | D6: 6 | E6: 2.3 | F6: 1 | I6: 2.5 | J6: =K6*4+L6*9+M6*4 -> 718 | K6: =D6*2+F6*1+G6*8+I6*7 -> 30.5 | L6: =E6*5+G6*8+I6*5 -> 24 | M6: =D6*15+F6*5+H6*15+G6*12 -> 95 | N6: =週菜單!B16 -> 西芹鮮菇
C7: =週菜單!B10 -> 滷香排骨 | D7: 6 | E7: 2.2 | F7: 1 | I7: 2.5 | J7: =K7*4+L7*9+M7*4 -> 713.5 | K7: =D7*2+F7*1+G7*8+I7*7 -> 30.5 | L7: =E7*5+G7*8+I7*5 -> 23.5 | M7: =D7*15+F7*5+H7*15+G7*12 -> 95 | N7: =週菜單!B17 -> 毛豆紅絲炒蛋
C8: =週菜單!B11 -> 香腸蛋炒飯 | D8: 5.5 | E8: 1.8 | F8: 1.2 | I8: 2 | J8: =K8*4+L8*9+M8*4 -> 629.8 | K8: =D8*2+F8*1+G8*8+I8*7 -> 26.2 | L8: =E8*5+G8*8+I8*5 -> 19 | M8: =D8*15+F8*5+H8*15+G8*12 -> 88.5
C9: =週菜單!B22 -> 滷味燙套餐 | D9: 4 | E9: 1.5 | F9: 1 | I9: 2.5 | J9: =K9*4+L9*9+M9*4 -> 546 | K9: =D9*2+F9*1+G9*8+I9*7 -> 26.5 | L9: =E9*5+G9*8+I9*5 -> 20 | M9: =D9*15+F9*5+H9*15+G9*12 -> 65
C10: =週菜單!B23 -> 玉米濃湯餃 | D10: 5 | E10: 1.5 | F10: 0.8 | I10: 2 | J10: =K10*4+L10*9+M10*4 -> 572.7 | K10: =D10*2+F10*1+G10*8+I10*7 -> 24.8 | L10: =E10*5+G10*8+I10*5 -> 17.5 | M10: =D10*15+F10*5+H10*15+G10*12 -> 79
C11: =週菜單!B24 -> 雞排乾拌麵 | D11: 4.5 | E11: 2.5 | F11: 0.8 | I11: 2 | J11: =K11*4+L11*9+M11*4 -> 583.7 | K11: =D11*2+F11*1+G11*8+I11*7 -> 23.8 | L11: =E11*5+G11*8+I11*5 -> 22.5 | M11: =D11*15+F11*5+H11*15+G11*12 -> 71.5
A12: =A4+1 -> 45979 | B12: =A12 -> 45979 | C12: =週菜單!H7 -> 雞腿飯 | D12: 5.8 | E12: 2.6 | F12: 1 | I12: 3 | J12: =K12*4+L12*9+M12*4 -> 754.4 | K12: =D12*2+F12*1+G12*8+I12*7 -> 33.6 | L12: =E12*5+G12*8+I12*5 -> 28 | M12: =D12*15+F12*5+H12*15+G12*12 -> 92 | N12: =週菜單!H14 -> 季節時蔬
C13: =週菜單!H8 -> 三杯雞丁 | D13: 5.3 | E13: 2.4 | F13: 1.1 | I13: 2 | J13: =K13*4+L13*9+M13*4 -> 640.8 | K13: =D13*2+F13*1+G13*8+I13*7 -> 25.7 | L13: =E13*5+G13*8+I13*5 -> 22 | M13: =D13*15+F13*5+H13*15+G13*12 -> 85 | N13: =週菜單!H15 -> 雙色南瓜
C14: =週菜單!H9 -> BBQ烤肉 | D14: 5.3 | E14: 2.2 | F14: 1 | I14: 2 | J14: =K14*4+L14*9+M14*4 -> 629.4 | K14: =D14*2+F14*1+G14*8+I14*7 -> 25.6 | L14: =E14*5+G14*8+I14*5 -> 21 | M14: =D14*15+F14*5+H14*15+G14*12 -> 84.5 | N14: =週菜單!H16 -> 玉筍花椰
C15: =週菜單!H10 -> 日式魚排 | D15: 5.8 | E15: 2.6 | F15: 1 | I15: 1.8 | J15: =K15*4+L15*9+M15*4 -> 666.8 | K15: =D15*2+F15*1+G15*8+I15*7 -> 25.2 | L15: =E15*5+G15*8+I15*5 -> 22 | M15: =D15*15+F15*5+H15*15+G15*12 -> 92 | N15: =週菜單!H17 -> 三色干絲
C16: =週菜單!H11 -> 紅燒牛肉燴飯 | D16: 5 | E16: 2 | F16: 1 | G16: 0.3 | I16: 2 | J16: =K16*4+L16*9+M16*4 -> 645.6 | K16: =D16*2+F16*1+G16*8+I16*7 -> 27.4 | L16: =E16*5+G16*8+I16*5 -> 22.4 | M16: =D16*15+F16*5+H16*15+G16*12 -> 83.6
C17: =週菜單!H22 -> 韓式部隊鍋 | D17: 4 | E17: 1 | F17: 0.8 | G17: 0.3 | I17: 2 | J17: =K17*4+L17*9+M17*4 -> 527.8 | K17: =D17*2+F17*1+G17*8+I17*7 -> 25.2 | L17: =E17*5+G17*8+I17*5 -> 17.4 | M17: =D17*15+F17*5+H17*15+G17*12 -> 67.6
C18: =週菜單!H23 -> 叉燒醬油拉麵 | D18: 4 | E18: 1.5 | F18: 1 | I18: 2 | J18: =K18*4+L18*9+M18*4 -> 509.5 | K18: =D18*2+F18*1+G18*8+I18*7 -> 23 | L18: =E18*5+G18*8+I18*5 -> 17.5 | M18: =D18*15+F18*5+H18*15+G18*12 -> 65
C19: =週菜單!H24 -> 滷蛋肉燥拌麵 | D19: 4.5 | E19: 1.5 | F19: 0.8 | I19: 2.5 | J19: =K19*4+L19*9+M19*4 -> 575.2 | K19: =D19*2+F19*1+G19*8+I19*7 -> 27.3 | L19: =E19*5+G19*8+I19*5 -> 20 | M19: =D19*15+F19*5+H19*15+G19*12 -> 71.5
A20: =A12+1 -> 45980 | B20: =A20 -> 45980 | C20: =週菜單!N7 -> 雞腿飯 | D20: 5.5 | E20: 2.6 | F20: 1.2 | I20: 3.6 | J20: =K20*4+L20*9+M20*4 -> 782.6 | K20: =D20*2+F20*1+G20*8+I20*7 -> 37.4 | L20: =E20*5+G20*8+I20*5 -> 31 | M20: =D20*15+F20*5+H20*15+G20*12 -> 88.5 | N20: =週菜單!N14 -> 季節時蔬
C21: =週菜單!N8 -> 椒鹽雞丁 | D21: 5 | E21: 2.4 | F21: 1.2 | I21: 2.6 | J21: =K21*4+L21*9+M21*4 -> 666.6 | K21: =D21*2+F21*1+G21*8+I21*7 -> 29.4 | L21: =E21*5+G21*8+I21*5 -> 25 | M21: =D21*15+F21*5+H21*15+G21*12 -> 81 | N21: =週菜單!N15 -> 青椒豆干
C22: =週菜單!N9 -> 招牌燒肉 | D22: 5 | E22: 2.3 | F22: 1.3 | I22: 2.6 | J22: =K22*4+L22*9+M22*4 -> 664.5 | K22: =D22*2+F22*1+G22*8+I22*7 -> 29.5 | L22: =E22*5+G22*8+I22*5 -> 24.5 | M22: =D22*15+F22*5+H22*15+G22*12 -> 81.5 | N22: =週菜單!N16 -> 三杯麵腸
C23: =週菜單!N10 -> 糖醋里肌 | D23: 5.5 | E23: 2.6 | F23: 1.2 | I23: 2.4 | J23: =K23*4+L23*9+M23*4 -> 695 | K23: =D23*2+F23*1+G23*8+I23*7 -> 29 | L23: =E23*5+G23*8+I23*5 -> 25 | M23: =D23*15+F23*5+H23*15+G23*12 -> 88.5 | N23: =週菜單!N17 -> 針菇大黃瓜
C24: =週菜單!N11 -> 火腿蛋炒飯 | D24: 4.5 | E24: 2 | F24: 0.9 | I24: 2 | J24: =K24*4+L24*9+M24*4 -> 563.6 | K24: =D24*2+F24*1+G24*8+I24*7 -> 23.9 | L24: =E24*5+G24*8+I24*5 -> 20 | M24: =D24*15+F24*5+H24*15+G24*12 -> 72
C25: =週菜單!N22 -> 什錦鍋燒意麵 | D25: 4 | E25: 1.5 | F25: 1 | I25: 2.5 | J25: =K25*4+L25*9+M25*4 -> 546 | K25: =D25*2+F25*1+G25*8+I25*7 -> 26.5 | L25: =E25*5+G25*8+I25*5 -> 20 | M25: =D25*15+F25*5+H25*15+G25*12 -> 65
C26: =週菜單!N23 -> 水餃 | D26: 5 | E26: 0.5 | F26: 1 | I26: 3 | J26: =K26*4+L26*9+M26*4 -> 605.5 | K26: =D26*2+F26*1+G26*8+I26*7 -> 32 | L26: =E26*5+G26*8+I26*5 -> 17.5 | M26: =D26*15+F26*5+H26*15+G26*12 -> 80
C27: =週菜單!N24 -> 白醬培根義大利麵 | D27: 4.5 | E27: 2.5 | F27: 0.5 | G27: 0.5 | I27: 2 | J27: =K27*4+L27*9+M27*4 -> 652.5 | K27: =D27*2+F27*1+G27*8+I27*7 -> 27.5 | L27: =E27*5+G27*8+I27*5 -> 26.5 | M27: =D27*15+F27*5+H27*15+G27*12 -> 76
A28: =A20+1 -> 45981 | B28: =A28 -> 45981 | C28: =週菜單!T7 -> 雞腿飯 | D28: 5.5 | E28: 2.6 | F28: 1.1 | I28: 3.5 | J28: =K28*4+L28*9+M28*4 -> 772.9 | K28: =D28*2+F28*1+G28*8+I28*7 -> 36.6 | L28: =E28*5+G28*8+I28*5 -> 30.5 | M28: =D28*15+F28*5+H28*15+G28*12 -> 88 | N28: =週菜單!T14 -> 季節時蔬
C29: =週菜單!T8 -> 鐵路便當 | D29: 5.5 | E29: 2.7 | F29: 1.1 | I29: 2.5 | J29: =K29*4+L29*9+M29*4 -> 704.4 | K29: =D29*2+F29*1+G29*8+I29*7 -> 29.6 | L29: =E29*5+G29*8+I29*5 -> 26 | M29: =D29*15+F29*5+H29*15+G29*12 -> 88 | N29: =週菜單!T15 -> 韭菜豆芽
C30: =週菜單!T9 -> 燒烤腿排 | D30: 5 | E30: 2.3 | F30: 1.3 | I30: 2.5 | J30: =K30*4+L30*9+M30*4 -> 657.2 | K30: =D30*2+F30*1+G30*8+I30*7 -> 28.8 | L30: =E30*5+G30*8+I30*5 -> 24 | M30: =D30*15+F30*5+H30*15+G30*12 -> 81.5 | N30: =週菜單!T16 -> 玉米豆腐
C31: =週菜單!T10 -> 宮保豬肉 | D31: 5.5 | E31: 2.6 | F31: 1.3 | I31: 2.3 | J31: =K31*4+L31*9+M31*4 -> 690.1 | K31: =D31*2+F31*1+G31*8+I31*7 -> 28.4 | L31: =E31*5+G31*8+I31*5 -> 24.5 | M31: =D31*15+F31*5+H31*15+G31*12 -> 89 | N31: =週菜單!T17 -> 塔香海帶根
C32: =週菜單!T11 -> 南蠻雞肉丼 | D32: 5.5 | E32: 2.5 | F32: 1 | I32: 2 | J32: =K32*4+L32*9+M32*4 -> 656.5 | K32: =D32*2+F32*1+G32*8+I32*7 -> 26 | L32: =E32*5+G32*8+I32*5 -> 22.5 | M32: =D32*15+F32*5+H32*15+G32*12 -> 87.5
C33: =週菜單!T22 -> 紅燒牛肉麵 | D33: 4 | E33: 1.5 | F33: 1.1 | I33: 2 | J33: =K33*4+L33*9+M33*4 -> 511.9 | K33: =D33*2+F33*1+G33*8+I33*7 -> 23.1 | L33: =E33*5+G33*8+I33*5 -> 17.5 | M33: =D33*15+F33*5+H33*15+G33*12 -> 65.5
C34: =週菜單!T23 -> 元氣小火鍋 | D34: 4 | E34: 1 | F34: 1 | I34: 1.3 | J34: =K34*4+L34*9+M34*4 -> 435.9 | K34: =D34*2+F34*1+G34*8+I34*7 -> 18.1 | L34: =E34*5+G34*8+I34*5 -> 11.5 | M34: =D34*15+F34*5+H34*15+G34*12 -> 65
C35: =週菜單!T24 -> 白油炒手麵 | D35: 4 | E35: 0.9 | F35: 1.1 | I35: 2.3 | J35: =K35*4+L35*9+M35*4 -> 506.8 | K35: =D35*2+F35*1+G35*8+I35*7 -> 25.2 | L35: =E35*5+G35*8+I35*5 -> 16 | M35: =D35*15+F35*5+H35*15+G35*12 -> 65.5
A36: =A28+1 -> 45982 | B36: =A36 -> 45982 | C36: =週菜單!Z7 -> 雞腿飯 | D36: 6 | E36: 2.7 | F36: 1.2 | I36: 2.8 | J36: =K36*4+L36*9+M36*4 -> 762.7 | K36: =D36*2+F36*1+G36*8+I36*7 -> 32.8 | L36: =E36*5+G36*8+I36*5 -> 27.5 | M36: =D36*15+F36*5+H36*15+G36*12 -> 96 | N36: =週菜單!Z14 -> 季節時蔬
C37: =週菜單!Z8 -> 香酥雞排 | D37: 6 | E37: 2.6 | F37: 1.2 | I37: 2.3 | J37: =K37*4+L37*9+M37*4 -> 721.7 | K37: =D37*2+F37*1+G37*8+I37*7 -> 29.3 | L37: =E37*5+G37*8+I37*5 -> 24.5 | M37: =D37*15+F37*5+H37*15+G37*12 -> 96 | N37: =週菜單!Z15 -> 小黃瓜素雞
C38: =週菜單!Z9 -> 紅燒雞丁 | D38: 5.5 | E38: 2.4 | F38: 1.3 | I38: 2.3 | J38: =K38*4+L38*9+M38*4 -> 681.1 | K38: =D38*2+F38*1+G38*8+I38*7 -> 28.4 | L38: =E38*5+G38*8+I38*5 -> 23.5 | M38: =D38*15+F38*5+H38*15+G38*12 -> 89 | N38: =週菜單!Z16 -> 咖哩洋芋
C39: =週菜單!Z10 -> 黑胡椒豬肉 | D39: 5.5 | E39: 2.2 | F39: 1.3 | I39: 2.3 | J39: =K39*4+L39*9+M39*4 -> 672.1 | K39: =D39*2+F39*1+G39*8+I39*7 -> 28.4 | L39: =E39*5+G39*8+I39*5 -> 22.5 | M39: =D39*15+F39*5+H39*15+G39*12 -> 89 | N39: =週菜單!Z17 -> 香菇四季豆
C40: =週菜單!Z11 -> 奶油培根燴飯 | D40: 4 | E40: 1.8 | F40: 0.8 | G40: 0.3 | I40: 2 | J40: =K40*4+L40*9+M40*4 -> 563.8 | K40: =D40*2+F40*1+G40*8+I40*7 -> 25.2 | L40: =E40*5+G40*8+I40*5 -> 21.4 | M40: =D40*15+F40*5+H40*15+G40*12 -> 67.6
...

Sheet 食登
A1: 學校* | B1: 日期* | C1: 出餐類型* | D1: 全穀雜糧* | E1: 油脂與堅果種子* | F1: 蔬菜* | G1: 乳品* | H1: 水果* | I1: 豆魚蛋肉* | J1: 熱量* | K1: 主食* | L1: 主食 | M1: 主菜 | N1: 主菜 | O1: 主菜 | P1: 主菜 | Q1: 副菜 | R1: 副菜 | S1: 副菜 | T1: 副菜 | U1: 副菜 | V1: 副菜 | W1: 蔬菜 | X1: 湯品 | Y1: 附餐 | Z1: 附餐 | AA1: 附餐
A2: 新北市泰山區泰山高中 | B2: =週菜單!A4 -> 45978 | C2: 午餐 | D2: 6 | E2: 3 | F2: 1.2 | G2: 0 | H2: 0 | I2: 3 | J2: 809 | K2: 白飯 | M2: =週菜單!B7 -> 雞腿飯 | N2: =週菜單!B8 -> 卡啦雞排飯 | O2: =週菜單!#REF! -> #REF! | P2: =週菜單!B9 -> 沙茶豬柳 | Q2: =週菜單!B22 -> 滷味燙套餐 | R2: =週菜單!B23 -> 玉米濃湯餃 | S2: =週菜單!B24 -> 雞排乾拌麵 | T2: =週菜單!#REF! -> #REF! | U2: =週菜單!B15 -> 泡菜冬粉 | V2: =週菜單!B16 -> 西芹鮮菇 | W2: =週菜單!B17 -> 毛豆紅絲炒蛋 | X2: =週菜單!B18 -> 0
A3: 新北市泰山區泰山高中 | B3: =週菜單!G4 -> 45979 | C3: 午餐 | D3: 6 | E3: 3 | F3: 1.2 | G3: 0 | H3: 0 | I3: 3 | J3: 809 | K3: 白飯 | M3: =週菜單!H7 -> 雞腿飯 | N3: =週菜單!H8 -> 三杯雞丁 | O3: =週菜單!#REF! -> #REF! | P3: =週菜單!H9 -> BBQ烤肉 | Q3: =週菜單!H22 -> 韓式部隊鍋 | R3: =週菜單!H23 -> 叉燒醬油拉麵 | S3: =週菜單!H24 -> 滷蛋肉燥拌麵 | T3: =週菜單!#REF! -> #REF! | U3: =週菜單!H15 -> 雙色南瓜 | V3: =週菜單!H16 -> 玉筍花椰 | W3: =週菜單!H17 -> 三色干絲 | X3: =週菜單!H18 -> 0
A4: 新北市泰山區泰山高中 | B4: =週菜單!M4 -> 45980 | C4: 午餐 | D4: 6 | E4: 3 | F4: 1.2 | G4: 0 | H4: 0 | I4: 3 | J4: 809 | K4: 白飯 | M4: =週菜單!N7 -> 雞腿飯 | N4: =週菜單!N8 -> 椒鹽雞丁 | O4: =週菜單!#REF! -> #REF! | P4: =週菜單!N9 -> 招牌燒肉 | Q4: =週菜單!N22 -> 什錦鍋燒意麵 | R4: =週菜單!N23 -> 水餃 | S4: =週菜單!N24 -> 白醬培根義大利麵 | T4: =週菜單!#REF! -> #REF! | U4: =週菜單!N15 -> 青椒豆干 | V4: =週菜單!N16 -> 三杯麵腸 | W4: =週菜單!N17 -> 針菇大黃瓜 | X4: =週菜單!N18 -> 0
A5: 新北市泰山區泰山高中 | B5: =週菜單!S4 -> 45981 | C5: 午餐 | D5: 6 | E5: 3 | F5: 1.2 | G5: 0 | H5: 0 | I5: 3 | J5: 809 | K5: 白飯 | M5: =週菜單!T7 -> 雞腿飯 | N5: =週菜單!T8 -> 鐵路便當 | O5: =週菜單!#REF! -> #REF! | P5: =週菜單!T9 -> 燒烤腿排 | Q5: =週菜單!T22 -> 紅燒牛肉麵 | R5: =週菜單!T23 -> 元氣小火鍋 | S5: =週菜單!T24 -> 白油炒手麵 | T5: =週菜單!#REF! -> #REF! | U5: =週菜單!T15 -> 韭菜豆芽 | V5: =週菜單!T16 -> 玉米豆腐 | W5: =週菜單!T17 -> 塔香海帶根 | X5: =週菜單!T18 -> 0
A6: 新北市泰山區泰山高中 | B6: =週菜單!Y4 -> 45982 | C6: 午餐 | D6: 6 | E6: 3 | F6: 1.2 | G6: 0 | H6: 0 | I6: 3 | J6: 809 | K6: 白飯 | M6: =週菜單!Z7 -> 雞腿飯 | N6: =週菜單!Z8 -> 香酥雞排 | O6: =週菜單!#REF! -> #REF! | P6: =週菜單!Z9 -> 紅燒雞丁 | Q6: =週菜單!Z22 -> 滷味燙套餐 | R6: =週菜單!Z23 -> 麻辣臭豆腐鴨血 | S6: =週菜單!Z24 -> 泡菜燒肉拌麵 | T6: =週菜單!#REF! -> #REF! | U6: =週菜單!Z15 -> 小黃瓜素雞 | V6: =週菜單!Z16 -> 咖哩洋芋 | W6: =週菜單!Z17 -> 香菇四季豆 | X6: =週菜單!Z18 -> 0

Sheet 麵食資料庫
A1: 餐別 | B1: 價格 | C1: 主要烹調方式 | D1: kcal | E1: 過敏原
A2: 味噌烏龍麵 | B2: 80 | D2: 487 | E2: DEFH
A3: 蒜味拳骨拉麵 | B3: 80 | D3: 490.7 | E3: DEFH
A4: 雞排乾拌麵 | B4: 80 | D4: 571 | E4: HJ
A5: 滷味燙套餐 | B5: 80 | D5: 467 | E5: DEFH
A6: 泰式叻沙燒肉麵 | B6: 80 | D6: 536.6 | E6: DH
A7: 白醬培根義大利麵 | B7: 80 | D7: 652.5 | E7: EHJ
A8: 什錦鍋燒意麵 | B8: 80 | D8: 491.2 | E8: DH
A9: 紅燒牛肉麵 | B9: 130 | D9: 500.5 | E9: H
A10: 豬排麻醬麵 | B10: 80 | D10: 568.4 | E10: BHK
A11: 沙茶豬肉火鍋 | B11: 80 | D11: 511.9 | E11: DH
A12: 韓式部隊鍋 | B12: 80 | D12: 571.5 | E12: CDHJ
A13: 白油炒手麵 | B13: 80 | D13: 615.5 | E13: H
... A24: 炸豬排乾拌麵 | B24: 80 | D24: 583.7 | E24: HJ
A25: 麻辣臭豆腐鴨血 | B25: 80 | E25: FH
A26: 高麗冬粉
A27: 奶香起司鍋 | E27: CDFH
A28: 重慶小麵(辣) | E28: BEFH
A29: 玉米濃湯餃 | B29: 80 | D29: 566 | E29: CEHJ
A30: 餛飩貢丸乾拌麵 | B30: 80 | D30: 595.2 | E30: DH
A31: 日式關東煮 | B31: 80 | D31: 435.9 | E31: DEFH
A32: 泰式酸辣燒肉拌麵 | B32: 80 | D32: 583.7 | E32: DH
A33: 酸辣湯餃 | B33: 80 | E33: EH | F33: Ａ甲殼類、Ｂ花生類、Ｃ奶類、D魚類、E蛋類、F豆類、G堅果類、H含麩類、I芒果、J含亞硝酸鹽類、K芝麻類
A34: 雞排麻醬麵 | B34: 80 | E34: BHK
A35: 元氣小火鍋 | B35: 80 | E35: DEH
A36: 日式咖哩炒烏龍 | B36: 80 | E36: DH
A37: 泡菜燒肉拌麵 | B37: 80 | E37: EFH
A38: 叉燒醬油拉麵 | B38: 80 | E38: DEH
A39: 韓式泡菜鍋 | B39: 80 | E39: DFH
A40: 京醬燒肉拌麵 | B40: 80 | E40: EH
A41: 麻油香菇雞腿麵 | B41: 80 | E41: FH
A42: 滷蛋肉燥拌麵 | B42: 80 | E42: EFH
A43: 培根什錦炒麵 | B43: 80 | E43: EHJ
B44: for空格
A45: 什錦花枝羹麵線 | B45: 80 | E45: DH
A46: 味噌燒肉烏龍麵 | E46: DEH
A47: 南洋肉骨茶麵 | E47: FH
A48: 日式照燒炒烏龍 | E48: DH
A49: 沙茶燒肉拌麵 | E49: EFH

Sheet 簡餐資料庫
A1: 餐別 | B1: 價格 | C1: 主要烹調方式 | D1: kcal | E1: 過敏原 | F1: Ａ甲殼類、Ｂ花生類、Ｃ奶類、D魚類、E蛋類、F豆類、G堅果類、H含麩類、I芒果、J含亞硝酸鹽類、K芝麻類
A2: 雞腿飯 | B2: 110 | D2: 782.6
A3: 糖醋雞丁 | B3: 85 | C3: 糖醋 | D3: 666.6 | E3: H
A4: 宮保豬肉 | B4: 85 | C4: 炒 | D4: 664.5
A5: 泰式花枝排 | B5: 85 | C5: 炸 | D5: 695 | E5: ADH
A6: 紅燒獅子頭蓋飯 | B6: 80 | C6: 滷 | D6: 563.6 | E6: E
A7: 彩椒雞丁 | B7: 85 | C7: 炒 | D7: 640.8
A8: 孜然烤肉 | B8: 85 | C8: 烤 | D8: 629.4
A9: 日式魚排 | B9: 85 | C9: 炸 | D9: 666.8 | E9: DH
A10: 滑蛋豬肉燴飯 | B10: 80 | C10: 煮 | D10: 611.5 | E10: E
A11: 墨西哥烤雞腿 | B11: 85 | C11: 烤 | D11: 718.3
A12: 沙茶肉片 | B12: 85 | C12: 炒 | D12: 718 | E12: D
A13: 滷香爌肉 | B13: 85 | C13: 滷 | D13: 713.5
A14: 培根蛋炒飯 | B14: 80 | C14: 炒 | D14: 558.1 | E14: EJ
A15: 黑胡椒豬排 | B15: 85 | C15: 烤 | D15: 704.4 | E15: H
A16: 招牌燒肉 | B16: 85 | C16: 烤 | D16: 657.2
A17: 香酥柳葉魚 | B17: 85 | C17: 炸 | D17: 690.1 | E17: DH
A18: 南蠻雞肉丼 | B18: 80 | C18: 燴 | D18: 614.3 | E18: H
A19: 彩椒干丁 | E19: F
A20: 酸菜麵腸 | E20: H
A21: 蒟蒻大黃瓜
A22: 雙色南瓜
A23: 玉筍花椰
A24: 西芹鮮菇
A25: 沙茶冬粉 | E25: D
A26: 三色干絲 | E26: F
A27: 玉米炒蛋 | E27: E
A28: 麻香黃豆芽
A29: 番茄豆腐 | E29: F
A30: 什錦海結
A31: 香酥雞排 | B31: 85 | C31: 燴 | D31: 733.1 | E31: H
A32: 三杯雞丁 | B32: 85 | C32: 炒 | D32: 715.3
A33: 泰式魚排 | B33: 85 | C33: 炸 | D33: 721.3 | E33: DH
A34: 蒲燒鯛蓋飯 | B34: 80 | C34: 燴 | D34: 576.4 | E34: D
A35: 秀珍菇胡瓜
A36: 螞蟻上樹
A37: 黑輪炒韭黃 | E37: D
A38: 南洋咖哩雞 | B38: 85 | C38: 烤 | D38: 688.4
A39: 蒜泥白肉 | B39: 85 | C39: 炒 | D39: 659.7
A40: 椒鹽里肌 | B40: 85 | C40: 炸 | D40: 711.7
...
